[exception_details.py]
  [test_exception_details[new WeakSet()-expected25-False\]]
    bug: https://bugzilla.mozilla.org/show_bug.cgi?id=1791715
    expected: FAIL

  [test_exception_details[new Error('SOME_ERROR_TEXT')-expected26-False\]]
    bug: https://bugzilla.mozilla.org/show_bug.cgi?id=1791715
    expected: FAIL

  [test_exception_details[Promise.resolve()-expected27-False\]]
    bug: https://bugzilla.mozilla.org/show_bug.cgi?id=1791715
    expected: FAIL

  [test_exception_details[new Int32Array()-expected28-False\]]
    bug: https://bugzilla.mozilla.org/show_bug.cgi?id=1791715
    expected: FAIL

  [test_exception_details[new ArrayBuffer()-expected29-False\]]
    bug: https://bugzilla.mozilla.org/show_bug.cgi?id=1791715
    expected: FAIL

  [test_exception_details[document.createElement('div')-expected30-False\]]
    bug: https://bugzilla.mozilla.org/show_bug.cgi?id=1791715
    expected: FAIL

  [test_exception_details[window-expected31-False\]]
    expected: FAIL
    bug: https://bugzilla.mozilla.org/show_bug.cgi?id=1791715
